<?xml version="1.0" ?>
<!-- =================================================================================== -->
<!-- |    This document was autogenerated by xacro from /home/meditab/agv_ws/src/hey_agv/urdf/dose_car.urdf.xacro | -->
<!-- |    EDITING THIS FILE BY HAND IS NOT RECOMMENDED                                 | -->
<!-- =================================================================================== -->
<robot name="my_robot">
  <material name="blue">
    <color rgba="0 0 0.5 1"/>
  </material>
  <material name="grey">
    <color rgba="0.5 0.5 0.5 1"/>
  </material>
  <material name="white">
    <color rgba="1.0 1.0 1.0 1"/>
  </material>
  <material name="silver">
    <color rgba="0.75 0.75 0.75 1"/>
  </material>
  <link name="base_link">
    <visual>
      <geometry>
        <mesh filename="file:///home/meditab/agv_ws/install/hey_agv/share/hey_agv/urdf/meshes/agv_base.dae"/>
      </geometry>
      <origin rpy="0 0 1.5708" xyz="0 0 0"/>
      <material name="blue"/>
    </visual>
    <inertial>
      <origin rpy="0 0 0" xyz="0 0 0"/>
      <mass value="18.0"/>
      <inertia ixx="0.350412" ixy="0" ixz="0" iyy="0.60531" iyz="0" izz="0.31538999999999995"/>
    </inertial>
    <collision>
      <geometry>
        <mesh filename="file:///home/meditab/agv_ws/install/hey_agv/share/hey_agv/urdf/meshes/agv_base.dae"/>
      </geometry>
      <origin rpy="0 0 1.5708" xyz="0 0 0"/>
    </collision>
  </link>
  <link name="right_wheel_link">
    <visual>
      <geometry>
        <cylinder length="0.05" radius="0.053"/>
      </geometry>
      <origin rpy="1.5707963267948966 0 0" xyz="0 0 0"/>
      <material name="red"/>
    </visual>
    <collision>
      <geometry>
        <cylinder length="0.05" radius="0.053"/>
      </geometry>
      <origin rpy="1.5707963267948966 0 0" xyz="0 0 0"/>
    </collision>
    <inertial>
      <origin rpy="1.5707963267948966 0 0" xyz="0 0 0"/>
      <mass value="0.5"/>
      <inertia ixx="0.0007677916666666667" ixy="0" ixz="0" iyy="0.0007677916666666667" iyz="0" izz="0.00070225"/>
    </inertial>
  </link>
  <link name="left_wheel_link">
    <visual>
      <geometry>
        <cylinder length="0.05" radius="0.053"/>
      </geometry>
      <origin rpy="1.5707963267948966 0 0" xyz="0 0 0"/>
      <material name="red"/>
    </visual>
    <collision>
      <geometry>
        <cylinder length="0.05" radius="0.053"/>
      </geometry>
      <origin rpy="1.5707963267948966 0 0" xyz="0 0 0"/>
    </collision>
    <inertial>
      <origin rpy="1.5707963267948966 0 0" xyz="0 0 0"/>
      <mass value="0.5"/>
      <inertia ixx="0.0007677916666666667" ixy="0" ixz="0" iyy="0.0007677916666666667" iyz="0" izz="0.00070225"/>
    </inertial>
  </link>
  <joint name="base_right_wheel_joint" type="continuous">
    <parent link="base_link"/>
    <child link="right_wheel_link"/>
    <origin rpy="0 0 0" xyz="0 0.183 0.041"/>
    <axis xyz="0 1 0"/>
  </joint>
  <joint name="base_left_wheel_joint" type="continuous">
    <parent link="base_link"/>
    <child link="left_wheel_link"/>
    <origin rpy="0 0 0" xyz="0 -0.183 0.041"/>
    <axis xyz="0 1 0"/>
  </joint>
  <link name="lidar_link_right">
    <visual>
      <geometry>
        <cylinder length="0.015" radius="0.03"/>
      </geometry>
      <origin rpy="0 0 0" xyz="0 0 0"/>
      <material name="white"/>
    </visual>
    <collision>
      <geometry>
        <cylinder length="0.015" radius="0.03"/>
      </geometry>
      <origin rpy="0 0 0" xyz="0 0 0"/>
    </collision>
  </link>
  <joint name="lidar_right_base_joint" type="fixed">
    <parent link="base_link"/>
    <child link="lidar_link_right"/>
    <origin rpy="0 0 0" xyz="0.115 -0.16789 0.12"/>
  </joint>
  <link name="lidar_link_left">
    <visual>
      <geometry>
        <cylinder length="0.015" radius="0.03"/>
      </geometry>
      <origin rpy="0 0 0" xyz="0 0 0"/>
      <material name="white"/>
    </visual>
    <collision>
      <geometry>
        <cylinder length="0.015" radius="0.03"/>
      </geometry>
      <origin rpy="0 0 0" xyz="0 0 0"/>
    </collision>
  </link>
  <joint name="lidar_left_base_joint" type="fixed">
    <parent link="base_link"/>
    <child link="lidar_link_left"/>
    <origin rpy="0 0 0" xyz="-0.115 0.16789 0.12"/>
  </joint>
  <!-- make a square lift -->
  <link name="lift_link">
    <visual>
      <geometry>
        <box size="0.184 0.306 0.1"/>
      </geometry>
      <origin rpy="0 0 0" xyz="0 0 0"/>
      <material name="silver"/>
    </visual>
    <collision>
      <geometry>
        <box size="0.184 0.306 0.1"/>
      </geometry>
      <origin rpy="0 0 0" xyz="0 0 0"/>
    </collision>
    <inertial>
      <origin rpy="0 0 0" xyz="0 0 0"/>
      <mass value="3.0"/>
      <inertia ixx="0.025909" ixy="0" ixz="0" iyy="0.031873" iyz="0" izz="0.010964"/>
    </inertial>
  </link>
  <joint name="lift_base_joint" type="prismatic">
    <parent link="base_link"/>
    <child link="lift_link"/>
    <origin rpy="0 0 1.5708" xyz="0 0 0"/>
    <limit effort="1000.0" lower="0.155" upper="0.187" velocity="1.0"/>
    <axis xyz="0 0 1"/>
  </joint>
  <gazebo reference="base_link">
    <material>Gazebo/Black</material>
  </gazebo>
  <gazebo reference="right_wheel_link">
    <material>Gazebo/Red</material>
  </gazebo>
  <gazebo reference="left_wheel_link">
    <material>Gazebo/Red</material>
  </gazebo>
  <gazebo reference="lidar_link_right">
    <material>Gazebo/White</material>
    <sensor name="gpu_lidar1" type="gpu_lidar">
      &quot;
            
      <pose relative_to="lidar_link_right">0 0 0 0 0 0</pose>
      <topic>lidar1</topic>
      <update_rate>10</update_rate>
      <ray>
        <scan>
          <horizontal>
            <samples>640</samples>
            <resolution>1</resolution>
            <min_angle>-3.14</min_angle>
            <max_angle>3.14</max_angle>
          </horizontal>
          <vertical>
            <samples>1</samples>
            <resolution>0.01</resolution>
            <min_angle>0</min_angle>
            <max_angle>0</max_angle>
          </vertical>
        </scan>
        <range>
          <min>0.08</min>
          <max>10.0</max>
          <resolution>0.01</resolution>
        </range>
      </ray>
      <always_on>1</always_on>
      <visualize>true</visualize>
    </sensor>
  </gazebo>
  <gazebo reference="lidar_link_left">
    <material>Gazebo/White</material>
    <sensor name="gpu_lidar2" type="gpu_lidar">
      &quot;
            
      <pose relative_to="lidar_link_left">0 0 0 0 0 0</pose>
      <topic>lidar2</topic>
      <update_rate>10</update_rate>
      <ray>
        <scan>
          <horizontal>
            <samples>640</samples>
            <resolution>1</resolution>
            <min_angle>-3.14</min_angle>
            <max_angle>3.14</max_angle>
          </horizontal>
          <vertical>
            <samples>1</samples>
            <resolution>0.01</resolution>
            <min_angle>0</min_angle>
            <max_angle>0</max_angle>
          </vertical>
        </scan>
        <range>
          <min>0.08</min>
          <max>10.0</max>
          <resolution>0.01</resolution>
        </range>
      </ray>
      <always_on>1</always_on>
      <visualize>true</visualize>
    </sensor>
  </gazebo>
  <gazebo>
    <plugin filename="gz-sim-diff-drive-system" name="gz::sim::systems::DiffDrive">
      <left_joint>base_left_wheel_joint</left_joint>
      <right_joint>base_right_wheel_joint</right_joint>
      <wheel_separation>0.366</wheel_separation>
      <wheel_radius>0.053</wheel_radius>
      <odom_publish_frequency>10</odom_publish_frequency>
      <topic>cmd_vel</topic>
    </plugin>
    <plugin filename="gz-sim-sensors-system" name="gz::sim::systems::Sensors">
      <render_engine>ogre2</render_engine>
    </plugin>
  </gazebo>
  <!-- <link name="caster_wheel_link"> 
        <visual>
            <geometry>
                <sphere radius="${wheel_radius / 2.0}" />
            </geometry>
            <origin xyz="0 0 0" rpy="0 0 0" />
            <material name="grey" />
        </visual>
        <collision>
            <geometry>
                <sphere radius="${wheel_radius / 2.0}" />
            </geometry>
             <origin xyz="0 0 0" rpy="0 0 0" />
        </collision>
        
        <xacro:sphere_inertia m="0.5" r="${wheel_radius / 2.0}" xyz="0 0 0" rpy="0 0 0" />
    </link>

    
        
    

    


    <joint name="base_joint" type="fixed">
        <parent link="base_link" />
        <child link="base_footprint" />
        <origin xyz="0 0 ${wheel_radius}" rpy="0 0 0"/>
    </joint>

    

    <joint name="base_caster_wheel_joint" type="fixed">
        <parent link="base_link" />
        <child link="caster_wheel_link" />
        <origin xyz="${base_length / 3.0} 0 ${-wheel_radius / 2.0}" rpy="0 0 0" />
    </joint> -->
</robot>
